<?xml version="1.0" ?>
<!-- =================================================================================== -->
<!-- |    This document was autogenerated by xacro from maze.urdf.xacro                | -->
<!-- |    EDITING THIS FILE BY HAND IS NOT RECOMMENDED                                 | -->
<!-- =================================================================================== -->
<robot name="maze">
  <material name="black">
    <color rgba="0 0 0 1"/>
  </material>
  <material name="red">
    <color rgba="0.8 0.1 0.1 1"/>
  </material>
  <material name="blue">
    <color rgba="0.1 0.1 0.9 1"/>
  </material>
  <material name="white">
    <color rgba="1 1 1 1"/>
  </material>
  <link name="base_link">
    <origin rpy="0.0 0.0 0.0" xyz="0 0 0.00"/>
    <visual>
      <geometry>
        <box size="5 5 0.001"/>
      </geometry>
    </visual>
  </link>
  <link name="obs_l1">
    <visual>
      <origin rpy="0.0 0.0 0.0" xyz="0.0 0.0 0.0"/>
      <geometry>
        <box size="0.1 0.8 0.01"/>
      </geometry>
      <material name="black"/>
    </visual>
    <collision>
      <origin rpy="0.0 0.0 0.0" xyz="0.0 0.0 0.0"/>
      <geometry>
        <box size="0.1 0.8 0.15"/>
      </geometry>
    </collision>
    <inertial>
      <mass value="10000"/>
      <inertia ixx="100" ixy="0" ixz="0" iyy="100" iyz="0" izz="100"/>
    </inertial>
  </link>
  <joint name="base_to_obs_l1" type="fixed">
    <parent link="base_link"/>
    <child link="obs_l1"/>
    <origin xyz="-0.4 0.0 0.0"/>
  </joint>
  <link name="obs_l2">
    <visual>
      <origin rpy="0.0 0.0 0.0" xyz="0.0 0.0 0.0"/>
      <geometry>
        <box size="0.3 0.1 0.01"/>
      </geometry>
      <material name="black"/>
    </visual>
    <collision>
      <origin rpy="0.0 0.0 0.0" xyz="0.0 0.0 0.0"/>
      <geometry>
        <box size="0.3 0.1 0.15"/>
      </geometry>
    </collision>
    <inertial>
      <mass value="10000"/>
      <inertia ixx="100" ixy="0" ixz="0" iyy="100" iyz="0" izz="100"/>
    </inertial>
  </link>
  <joint name="base_to_obs_l2" type="fixed">
    <parent link="base_link"/>
    <child link="obs_l2"/>
    <origin xyz="-0.25 0.4 0.0"/>
  </joint>
  <link name="obs_l3">
    <visual>
      <origin rpy="0.0 0.0 0.0" xyz="0.0 0.0 0.0"/>
      <geometry>
        <box size="0.3 0.1 0.01"/>
      </geometry>
      <material name="black"/>
    </visual>
    <collision>
      <origin rpy="0.0 0.0 0.0" xyz="0.0 0.0 0.0"/>
      <geometry>
        <box size="0.3 0.1 0.15"/>
      </geometry>
    </collision>
    <inertial>
      <mass value="10000"/>
      <inertia ixx="100" ixy="0" ixz="0" iyy="100" iyz="0" izz="100"/>
    </inertial>
  </link>
  <joint name="base_to_obs_l3" type="fixed">
    <parent link="base_link"/>
    <child link="obs_l3"/>
    <origin xyz="-0.25 -0.4 0.0"/>
  </joint>
  <link name="obs_r1">
    <visual>
      <origin rpy="0.0 0.0 0.0" xyz="0.0 0.0 0.0"/>
      <geometry>
        <box size="0.1 0.8 0.01"/>
      </geometry>
      <material name="black"/>
    </visual>
    <collision>
      <origin rpy="0.0 0.0 0.0" xyz="0.0 0.0 0.0"/>
      <geometry>
        <box size="0.1 0.8 0.15"/>
      </geometry>
    </collision>
    <inertial>
      <mass value="10000"/>
      <inertia ixx="100" ixy="0" ixz="0" iyy="100" iyz="0" izz="100"/>
    </inertial>
  </link>
  <joint name="base_to_obs_r1" type="fixed">
    <parent link="base_link"/>
    <child link="obs_r1"/>
    <origin xyz="0.4 0.0 0.0"/>
  </joint>
  <link name="obs_r2">
    <visual>
      <origin rpy="0.0 0.0 0.0" xyz="0.0 0.0 0.0"/>
      <geometry>
        <box size="0.3 0.1 0.01"/>
      </geometry>
      <material name="black"/>
    </visual>
    <collision>
      <origin rpy="0.0 0.0 0.0" xyz="0.0 0.0 0.0"/>
      <geometry>
        <box size="0.3 0.1 0.15"/>
      </geometry>
    </collision>
    <inertial>
      <mass value="10000"/>
      <inertia ixx="100" ixy="0" ixz="0" iyy="100" iyz="0" izz="100"/>
    </inertial>
  </link>
  <joint name="base_to_obs_r2" type="fixed">
    <parent link="base_link"/>
    <child link="obs_r2"/>
    <origin xyz="0.25 0.4 0.0"/>
  </joint>
  <link name="obs_r3">
    <visual>
      <origin rpy="0.0 0.0 0.0" xyz="0.0 0.0 0.0"/>
      <geometry>
        <box size="0.3 0.1 0.01"/>
      </geometry>
      <material name="black"/>
    </visual>
    <collision>
      <origin rpy="0.0 0.0 0.0" xyz="0.0 0.0 0.0"/>
      <geometry>
        <box size="0.3 0.1 0.15"/>
      </geometry>
    </collision>
    <inertial>
      <mass value="10000"/>
      <inertia ixx="100" ixy="0" ixz="0" iyy="100" iyz="0" izz="100"/>
    </inertial>
  </link>
  <joint name="base_to_obs_r3" type="fixed">
    <parent link="base_link"/>
    <child link="obs_r3"/>
    <origin xyz="0.25 -0.4 0.0"/>
  </joint>
  <link name="obs_t1">
    <visual>
      <origin rpy="0.0 0.0 0.0" xyz="0.0 0.0 0.0"/>
      <geometry>
        <box size="1.4 0.1 0.01"/>
      </geometry>
      <material name="black"/>
    </visual>
    <collision>
      <origin rpy="0.0 0.0 0.0" xyz="0.0 0.0 0.0"/>
      <geometry>
        <box size="1.4 0.1 0.15"/>
      </geometry>
    </collision>
    <inertial>
      <mass value="10000"/>
      <inertia ixx="100" ixy="0" ixz="0" iyy="100" iyz="0" izz="100"/>
    </inertial>
  </link>
  <joint name="base_to_obs_t1" type="fixed">
    <parent link="base_link"/>
    <child link="obs_t1"/>
    <origin xyz="0.0 0.7 0.0"/>
  </joint>
  <link name="obs_t2">
    <visual>
      <origin rpy="0.0 0.0 0.0" xyz="0.0 0.0 0.0"/>
      <geometry>
        <box size="0.1 0.5 0.01"/>
      </geometry>
      <material name="black"/>
    </visual>
    <collision>
      <origin rpy="0.0 0.0 0.0" xyz="0.0 0.0 0.0"/>
      <geometry>
        <box size="0.1 0.5 0.15"/>
      </geometry>
    </collision>
    <inertial>
      <mass value="10000"/>
      <inertia ixx="100" ixy="0" ixz="0" iyy="100" iyz="0" izz="100"/>
    </inertial>
  </link>
  <joint name="base_to_obs_t2" type="fixed">
    <parent link="base_link"/>
    <child link="obs_t2"/>
    <origin xyz="-0.7 0.44999999999999996 0.0"/>
  </joint>
  <link name="obs_t3">
    <visual>
      <origin rpy="0.0 0.0 0.0" xyz="0.0 0.0 0.0"/>
      <geometry>
        <box size="0.1 0.5 0.01"/>
      </geometry>
      <material name="black"/>
    </visual>
    <collision>
      <origin rpy="0.0 0.0 0.0" xyz="0.0 0.0 0.0"/>
      <geometry>
        <box size="0.1 0.5 0.15"/>
      </geometry>
    </collision>
    <inertial>
      <mass value="10000"/>
      <inertia ixx="100" ixy="0" ixz="0" iyy="100" iyz="0" izz="100"/>
    </inertial>
  </link>
  <joint name="base_to_obs_t3" type="fixed">
    <parent link="base_link"/>
    <child link="obs_t3"/>
    <origin xyz="0.7 0.44999999999999996 0.0"/>
  </joint>
  <link name="obs_b1">
    <visual>
      <origin rpy="0.0 0.0 0.0" xyz="0.0 0.0 0.0"/>
      <geometry>
        <box size="1.4 0.1 0.01"/>
      </geometry>
      <material name="black"/>
    </visual>
    <collision>
      <origin rpy="0.0 0.0 0.0" xyz="0.0 0.0 0.0"/>
      <geometry>
        <box size="1.4 0.1 0.15"/>
      </geometry>
    </collision>
    <inertial>
      <mass value="10000"/>
      <inertia ixx="100" ixy="0" ixz="0" iyy="100" iyz="0" izz="100"/>
    </inertial>
  </link>
  <joint name="base_to_obs_b1" type="fixed">
    <parent link="base_link"/>
    <child link="obs_b1"/>
    <origin xyz="0.0 -0.7 0.0"/>
  </joint>
  <link name="obs_b2">
    <visual>
      <origin rpy="0.0 0.0 0.0" xyz="0.0 0.0 0.0"/>
      <geometry>
        <box size="0.1 0.5 0.01"/>
      </geometry>
      <material name="black"/>
    </visual>
    <collision>
      <origin rpy="0.0 0.0 0.0" xyz="0.0 0.0 0.0"/>
      <geometry>
        <box size="0.1 0.5 0.15"/>
      </geometry>
    </collision>
    <inertial>
      <mass value="10000"/>
      <inertia ixx="100" ixy="0" ixz="0" iyy="100" iyz="0" izz="100"/>
    </inertial>
  </link>
  <joint name="base_to_obs_b2" type="fixed">
    <parent link="base_link"/>
    <child link="obs_b2"/>
    <origin xyz="-0.7 -0.44999999999999996 0.0"/>
  </joint>
  <link name="obs_b3">
    <visual>
      <origin rpy="0.0 0.0 0.0" xyz="0.0 0.0 0.0"/>
      <geometry>
        <box size="0.1 0.5 0.01"/>
      </geometry>
      <material name="black"/>
    </visual>
    <collision>
      <origin rpy="0.0 0.0 0.0" xyz="0.0 0.0 0.0"/>
      <geometry>
        <box size="0.1 0.5 0.15"/>
      </geometry>
    </collision>
    <inertial>
      <mass value="10000"/>
      <inertia ixx="100" ixy="0" ixz="0" iyy="100" iyz="0" izz="100"/>
    </inertial>
  </link>
  <joint name="base_to_obs_b3" type="fixed">
    <parent link="base_link"/>
    <child link="obs_b3"/>
    <origin xyz="0.7 -0.44999999999999996 0.0"/>
  </joint>
  <!--   <xacro:obs name="w1" l="2.0" b="0.1" x="0" y="1.0"/>-->
  <!--   <xacro:obs name="w2" l="2.0" b="0.1" x="0" y="-1.0"/>-->
  <!--   <xacro:obs name="w3" l=".1" b="2.0" x="-1.0" y="0.0"/>-->
  <!--   <xacro:obs name="w4" l=".1" b="2.0" x="1.0" y="0.0"/>-->
  <link name="bot_x">
    <origin rpy="0.0 0.0 0.0" xyz="0.0 0.0 0.0"/>
  </link>
  <link name="bot">
    <visual>
      <origin rpy="0.0 0.0 0.0" xyz="0 0 0.03"/>
      <geometry>
        <cylinder length="0.05" radius="0.05"/>
      </geometry>
      <material name="red"/>
    </visual>
    <collision>
      <origin rpy="0.0 0.0 0.0" xyz="0 0 0.03"/>
      <geometry>
        <cylinder length="0.05" radius="0.05"/>
      </geometry>
    </collision>
    <inertial>
      <origin rpy="0 0 0" xyz="0 0 0"/>
      <mass value="0.2"/>
    </inertial>
  </link>
  <joint name="base_to_bot_x" type="prismatic">
    <parent link="base_link"/>
    <child link="bot_x"/>
    <origin rpy="0 0 0" xyz="0 0 0.01"/>
    <axis xyz="1 0 0"/>
  </joint>
  <joint name="bot_x_to_bot" type="prismatic">
    <parent link="bot_x"/>
    <child link="bot"/>
    <origin rpy="0 0 0" xyz="0 0 0.01"/>
    <axis xyz="0 1 0"/>
  </joint>
</robot>
