<?xml version="1.0" encoding="utf-8"?>

<robot name="robot">

    <material name="black">
        <color rgba="0 0 0 1"/>
    </material>
    <material name="red">
        <color rgba="0.8 0.1 0.1 1"/>
    </material>
    <material name="blue">
        <color rgba="0.1 0.1 0.9 1"/>
    </material>
    <material name="white">
        <color rgba="1 1 1 1"/>
    </material>

    <link name="base_link">
        <origin rpy="0.0 0.0 0.0" xyz="0 0 0.00"/>
        <visual>
            <!-- <origin rpy="0.0 0.0 0.0" xyz="0.0 0.0 0.0"/> -->
            <geometry>
                <box size="5 5 0.001"/>
            </geometry>
        </visual>
    </link>

    <!-- Obstacle L1 (top right) -->
    <link name="obs_L1_1">
        <visual>
            <origin rpy="0.0 0.0 0.0" xyz="0.0 0.0 0.0"/>
            <geometry>
                <box size="0.7 0.1 0.01"/>
            </geometry>
            <material name="black"/>
        </visual>
        <collision>
            <origin rpy="0.0 0.0 0.0" xyz="0.0 0.0 0.0"/>
            <geometry>
                <box size="0.7 0.1 0.15"/>
            </geometry>
        </collision>
        <inertial>
            <mass value="10000"/>
            <inertia ixx="100"  ixy="0"  ixz="0" iyy="100" iyz="0" izz="100" />
        </inertial>
    </link>
    <link name="obs_L1_2">
        <visual>
            <origin rpy="0.0 0.0 0.0" xyz="0.0 0.0 0.0"/>
            <geometry>
                <box size="0.1 0.7 0.01"/>
            </geometry>
            <material name="black"/>
        </visual>
        <collision>
            <origin rpy="0.0 0.0 0.0" xyz="0.0 0.0 0.0"/>
            <geometry>
                <box size="0.1 0.7 0.15"/>
            </geometry>
        </collision>
        <inertial>
            <mass value="10000"/>
            <inertia ixx="100"  ixy="0"  ixz="0" iyy="100" iyz="0" izz="100" />
        </inertial>
    </link>
    <joint name="obs_L1_1" type="fixed">
        <parent link="base_link"/>
        <child link="obs_L1_1"/>
        <origin rpy="0 0 0" xyz="0.6 0.3 0"/>
    </joint>
    <joint name="obs_L1_2" type="fixed">
        <parent link="base_link"/>
        <child link="obs_L1_2"/>
        <origin rpy="0 0 0" xyz="0.3 0.6 0"/>
    </joint>

    <!-- Obstacle L2 (bottom left) -->
    <link name="obs_L2_1">
        <visual>
            <origin rpy="0.0 0.0 0.0" xyz="0.0 0.0 0.0"/>
            <geometry>
                <box size="0.7 0.1 0.01"/>
            </geometry>
            <material name="black"/>
        </visual>
        <collision>
            <origin rpy="0.0 0.0 0.0" xyz="0.0 0.0 0.0"/>
            <geometry>
                <box size="0.7 0.1 0.15"/>
            </geometry>
        </collision>
        <inertial>
            <mass value="10000"/>
            <inertia ixx="100"  ixy="0"  ixz="0" iyy="100" iyz="0" izz="100" />
        </inertial>
    </link>
    <link name="obs_L2_2">
        <visual>
            <origin rpy="0.0 0.0 0.0" xyz="0.0 0.0 0.0"/>
            <geometry>
                <box size="0.1 0.7 0.01"/>
            </geometry>
            <material name="black"/>
        </visual>
        <collision>
            <origin rpy="0.0 0.0 0.0" xyz="0.0 0.0 0.0"/>
            <geometry>
                <box size="0.1 0.7 0.15"/>
            </geometry>
        </collision>
        <inertial>
            <mass value="10000"/>
            <inertia ixx="100"  ixy="0"  ixz="0" iyy="100" iyz="0" izz="100" />
        </inertial>
    </link>
    <joint name="obs_L2_1" type="fixed">
        <parent link="base_link"/>
        <child link="obs_L2_1"/>
        <origin rpy="0 0 0" xyz="-0.6 -0.3 0"/>
    </joint>
    <joint name="obs_L2_2" type="fixed">
        <parent link="base_link"/>
        <child link="obs_L2_2"/>
        <origin rpy="0 0 0" xyz="-0.3 -0.6 0"/>
    </joint>


    <!-- Obstacle L2 (bottom right) -->
     <link name="obs_L3_1">
        <visual>
            <origin rpy="0.0 0.0 0.0" xyz="0.0 0.0 0.0"/>
            <geometry>
                <box size="0.7 0.1 0.01"/>
            </geometry>
            <material name="black"/>
        </visual>
        <collision>
            <origin rpy="0.0 0.0 0.0" xyz="0.0 0.0 0.0"/>
            <geometry>
                <box size="0.7 0.1 0.15"/>
            </geometry>
        </collision>
        <inertial>
            <mass value="10000"/>
            <inertia ixx="100"  ixy="0"  ixz="0" iyy="100" iyz="0" izz="100" />
        </inertial>
    </link>
     <link name="obs_L3_2">
        <visual>
            <origin rpy="0.0 0.0 0.0" xyz="0.0 0.0 0.0"/>
            <geometry>
                <box size="0.1 0.7 0.01"/>
            </geometry>
            <material name="black"/>
        </visual>
        <collision>
            <origin rpy="0.0 0.0 0.0" xyz="0.0 0.0 0.0"/>
            <geometry>
                <box size="0.1 0.7 0.15"/>
            </geometry>
        </collision>
        <inertial>
            <mass value="10000"/>
            <inertia ixx="100"  ixy="0"  ixz="0" iyy="100" iyz="0" izz="100" />
        </inertial>
    </link>
    <joint name="obs_L3_1" type="fixed">
        <parent link="base_link"/>
        <child link="obs_L3_1"/>
        <origin rpy="0 0 0" xyz="0.6 -0.3 0"/>
    </joint>
    <joint name="obs_L3_2" type="fixed">
        <parent link="base_link"/>
        <child link="obs_L3_2"/>
        <origin rpy="0 0 0" xyz="0.3 -0.6 0"/>
    </joint>


     <link name="obs_L4_1">
        <visual>
            <origin rpy="0.0 0.0 0.0" xyz="0.0 0.0 0.0"/>
            <geometry>
                <box size="0.7 0.1 0.01"/>
            </geometry>
            <material name="black"/>
        </visual>
        <collision>
            <origin rpy="0.0 0.0 0.0" xyz="0.0 0.0 0.0"/>
            <geometry>
                <box size="0.7 0.1 0.15"/>
            </geometry>
        </collision>
        <inertial>
            <mass value="10000"/>
            <inertia ixx="100"  ixy="0"  ixz="0" iyy="100" iyz="0" izz="100" />
        </inertial>
    </link>
     <link name="obs_L4_2">
        <visual>
            <origin rpy="0.0 0.0 0.0" xyz="0.0 0.0 0.0"/>
            <geometry>
                <box size="0.1 0.7 0.01"/>
            </geometry>
            <material name="black"/>
        </visual>
        <collision>
            <origin rpy="0.0 0.0 0.0" xyz="0.0 0.0 0.0"/>
            <geometry>
                <box size="0.1 0.7 0.15"/>
            </geometry>
        </collision>
        <inertial>
            <mass value="10000"/>
            <inertia ixx="100"  ixy="0"  ixz="0" iyy="100" iyz="0" izz="100" />
        </inertial>
    </link>
    <joint name="obs_L4_1" type="fixed">
        <parent link="base_link"/>
        <child link="obs_L4_1"/>
        <origin rpy="0 0 0" xyz="-0.6 0.3 0"/>
    </joint>
    <joint name="obs_L4_2" type="fixed">
        <parent link="base_link"/>
        <child link="obs_L4_2"/>
        <origin rpy="0 0 0" xyz="-0.3 0.6 0"/>
    </joint>




    <link name="bot_x">
        <origin rpy="0.0 0.0 0.0" xyz="0.0 0.0 0.0"/>
    </link>

    <link name="bot">
        <visual>
            <origin rpy="0.0 0.0 0.0" xyz="0 0 0.03"/>
            <geometry>
                <cylinder radius="0.05" length="0.05"/>
            </geometry>
            <material name="red"/>
        </visual>
        <collision>
            <origin rpy="0.0 0.0 0.0" xyz="0 0 0.03"/>
            <geometry>
                <cylinder radius="0.05" length="0.05"/>
            </geometry>
        </collision>
        <inertial>
            <origin xyz="0 0 0" rpy="0 0 0"/>
            <mass value="0.2"/>
        </inertial>
    </link>

    <joint name="base_to_bot_x" type="prismatic">
        <parent link="base_link"/>
        <child link="bot_x"/>
        <origin rpy="0 0 0" xyz="0 0 0.01"/>
        <axis xyz="1 0 0"/>
    </joint>

    <joint name="bot_x_to_bot" type="prismatic">
        <parent link="bot_x"/>
        <child link="bot"/>
        <origin rpy="0 0 0" xyz="0 0 0.01"/>
        <axis xyz="0 1 0"/>
    </joint>

</robot>