<?xml version="1.0"?>
<robot xmlns:xacro="http://www.ros.org/wiki/xacro" name="maze">

    <material name="black">
        <color rgba="0 0 0 1"/>
    </material>
    <material name="red">
        <color rgba="0.8 0.1 0.1 1"/>
    </material>
    <material name="blue">
        <color rgba="0.1 0.1 0.9 1"/>
    </material>
    <material name="white">
        <color rgba="1 1 1 1"/>
    </material>

    <link name="base_link">
        <origin rpy="0.0 0.0 0.0" xyz="0 0 0.00"/>
        <visual>
            <geometry>
                <box size="5 5 0.001"/>
            </geometry>
        </visual>
    </link>

    <xacro:macro name="obs" params="name l b x y">
    <link name="obs_${name}">
        <visual>
            <origin rpy="0.0 0.0 0.0" xyz="0.0 0.0 0.0"/>
            <geometry>
                <box size="${l} ${b} 0.01"/>
            </geometry>
            <material name="black"/>
        </visual>
        <collision>
            <origin rpy="0.0 0.0 0.0" xyz="0.0 0.0 0.0"/>
            <geometry>
                <box size="${l} ${b} 0.15"/>
            </geometry>
        </collision>
        <inertial>
            <mass value="10000"/>
            <inertia ixx="100"  ixy="0"  ixz="0" iyy="100" iyz="0" izz="100" />
        </inertial>
    </link>

    <joint name="base_to_obs_${name}" type="fixed">
        <parent link="base_link"/>
        <child link="obs_${name}"/>
        <origin xyz="${x} ${y} 0.0"/>
    </joint>
    </xacro:macro>

    <xacro:macro name="bot" params="radius mass">
    <link name="bot_x">
         <origin rpy="0.0 0.0 0.0" xyz="0.0 0.0 0.0"/>
    </link>
    <link name="bot">
        <visual>
            <origin rpy="0.0 0.0 0.0" xyz="0 0 0.03"/>
            <geometry>
                <cylinder radius="${radius}" length="0.05"/>
            </geometry>
            <material name="red"/>
        </visual>
        <collision>
            <origin rpy="0.0 0.0 0.0" xyz="0 0 0.03"/>
            <geometry>
                <cylinder radius="${radius}" length="0.05"/>
            </geometry>
        </collision>
        <inertial>
            <origin xyz="0 0 0" rpy="0 0 0"/>
            <mass value="${mass}"/>
        </inertial>
    </link>

    <joint name="base_to_bot_x" type="prismatic">
        <parent link="base_link"/>
        <child link="bot_x"/>
        <origin rpy="0 0 0" xyz="0 0 0.01"/>
        <axis xyz="1 0 0"/>
    </joint>

    <joint name="bot_x_to_bot" type="prismatic">
        <parent link="bot_x"/>
        <child link="bot"/>
        <origin rpy="0 0 0" xyz="0 0 0.01"/>
        <axis xyz="0 1 0"/>
    </joint>
    </xacro:macro>

   <xacro:obs name="l1" l="0.1" b="0.8" x="-0.4" y="0.0"/>
   <xacro:obs name="l2" l="0.3" b="0.1" x="${-0.4+0.15}" y="0.4"/>
   <xacro:obs name="l3" l="0.3" b="0.1" x="${-0.4+0.15}" y="-0.4"/>

   <xacro:obs name="r1" l="0.1" b="0.8" x="0.4" y="0.0"/>
   <xacro:obs name="r2" l="0.3" b="0.1" x="${0.4-0.15}" y="0.4"/>
   <xacro:obs name="r3" l="0.3" b="0.1" x="${0.4-0.15}" y="-0.4"/>

   <xacro:obs name="t1" l="1.4" b="0.1" x="0.0" y="0.7"/>
   <xacro:obs name="t2" l="0.1" b="0.5" x="-0.7" y="${0.7-0.25}"/>
   <xacro:obs name="t3" l="0.1" b="0.5" x="0.7" y="${0.7-0.25}"/>

   <xacro:obs name="b1" l="1.4" b="0.1" x="0.0" y="-0.7"/>
   <xacro:obs name="b2" l="0.1" b="0.5" x="-0.7" y="${-0.7+0.25}"/>
   <xacro:obs name="b3" l="0.1" b="0.5" x="0.7" y="${-0.7+0.25}"/>

<!--   <xacro:obs name="w1" l="2.0" b="0.1" x="0" y="1.0"/>-->
<!--   <xacro:obs name="w2" l="2.0" b="0.1" x="0" y="-1.0"/>-->
<!--   <xacro:obs name="w3" l=".1" b="2.0" x="-1.0" y="0.0"/>-->
<!--   <xacro:obs name="w4" l=".1" b="2.0" x="1.0" y="0.0"/>-->

   <xacro:bot radius="0.05" mass="0.2"/>

</robot>