<?xml version="1.0" encoding="utf-8"?>

<robot name="robot">

    <material name="black">
        <color rgba="0 0 0 1"/>
    </material>
    <material name="red">
        <color rgba="0.8 0.1 0.1 1"/>
    </material>
    <material name="green">
        <color rgba="0.1 0.9 0.1 1"/>
    </material>
    <material name="white">
        <color rgba="1 1 1 1"/>
    </material>

    <link name="base_link">
        <origin rpy="0.0 0.0 0.0" xyz="0 0 0.00"/>
        <visual>
            <!-- <origin rpy="0.0 0.0 0.0" xyz="0.0 0.0 0.0"/> -->
            <geometry>
                <box size="10 10 0.001"/>
            </geometry>
        </visual>
    </link>

    <!-- <link name="maze">
        <visual>
            <origin rpy="0.0 0.0 0.0" xyz="0.0 0.0 0.0"/>
            <geometry>
                <mesh filename="package://maze/urdf/meshes/maze.stl"/>
            </geometry>
        </visual>
        <collision>
            <origin rpy="0.0 0.0 0.0" xyz="0.0 0.0 0.0"/>
            <geometry>
                <mesh filename="package://maze/urdf/meshes/maze.stl"/>
            </geometry>
        </collision>
        <inertial>
            <mass value="10000"/>
            <inertia ixx="100"  ixy="0"  ixz="0" iyy="100" iyz="0" izz="100" />
        </inertial>
    </link> -->

    <link name="wall_left">
        <visual>
            <origin rpy="0.0 0.0 0.0" xyz="0.0 0.0 0.0"/>
            <geometry>
                <box size="0.05 1.05 0.05"/>
            </geometry>
            <material name="black"/>
        </visual>
        <collision>
            <origin rpy="0.0 0.0 0.0" xyz="0.0 0.0 0.0"/>
            <geometry>
                <box size="0.05 1 0.15"/>
            </geometry>
        </collision>
        <inertial>
            <mass value="10000"/>
            <inertia ixx="100"  ixy="0"  ixz="0" iyy="100" iyz="0" izz="100" />
        </inertial>
    </link>

    <joint name="base_to_wall_left" type="fixed">
        <parent link="base_link"/>
        <child link="wall_left"/>
        <origin rpy="0 0 0" xyz="-0.5 0 0"/>
    </joint>


    <link name="wall_right">
        <visual>
            <origin rpy="0.0 0.0 0.0" xyz="0.0 0.0 0.0"/>
            <geometry>
                <box size="0.05 1.05 0.05"/>
            </geometry>
            <material name="black"/>
        </visual>
        <collision>
            <origin rpy="0.0 0.0 0.0" xyz="0.0 0.0 0.0"/>
            <geometry>
                <box size="0.05 1 0.15"/>
            </geometry>
        </collision>
        <inertial>
            <mass value="10000"/>
            <inertia ixx="100"  ixy="0"  ixz="0" iyy="100" iyz="0" izz="100" />
        </inertial>
    </link>

    <joint name="base_to_wall_right" type="fixed">
        <parent link="base_link"/>
        <child link="wall_right"/>
        <origin rpy="0 0 0" xyz="3.5 0 0"/>
    </joint>


     <link name="wall_top">
        <visual>
            <origin rpy="0.0 0.0 0.0" xyz="0.0 0.0 0.0"/>
            <geometry>
                <box size="4.0 0.05 0.05"/>
            </geometry>
            <material name="black"/>
        </visual>
        <collision>
            <origin rpy="0.0 0.0 0.0" xyz="0.0 0.0 0.0"/>
            <geometry>
                <box size="4.0 0.05 0.15"/>
            </geometry>
        </collision>
        <inertial>
            <mass value="10000"/>
            <inertia ixx="100"  ixy="0"  ixz="0" iyy="100" iyz="0" izz="100" />
        </inertial>
    </link>

    <joint name="base_to_wall_top" type="fixed">
        <parent link="base_link"/>
        <child link="wall_top"/>
        <origin rpy="0 0 0" xyz="1.5 0.5 0"/>
    </joint>

    <link name="wall_bottom">
        <visual>
            <origin rpy="0.0 0.0 0.0" xyz="0.0 0.0 0.0"/>
            <geometry>
                <box size="4.0 0.05 0.05"/>
            </geometry>
            <material name="black"/>
        </visual>
        <collision>
            <origin rpy="0.0 0.0 0.0" xyz="0.0 0.0 0.0"/>
            <geometry>
                <box size="4.0 0.05 0.15"/>
            </geometry>
        </collision>
        <inertial>
            <mass value="10000"/>
            <inertia ixx="100"  ixy="0"  ixz="0" iyy="100" iyz="0" izz="100" />
        </inertial>
    </link>

    <joint name="base_to_wall_bottom" type="fixed">
        <parent link="base_link"/>
        <child link="wall_bottom"/>
        <origin rpy="0 0 0" xyz="1.5 -0.5 0"/>
    </joint>


    <link name="obs_left">
        <visual>
            <origin rpy="0.0 0.0 0.0" xyz="0.0 0.0 0.0"/>
            <geometry>
                <box size="0.05 0.8 0.05"/>
            </geometry>
            <material name="black"/>
        </visual>
        <collision>
            <origin rpy="0.0 0.0 0.0" xyz="0.0 0.0 0.0"/>
            <geometry>
                <box size="0.05 0.80 0.15"/>
            </geometry>
        </collision>
        <inertial>
            <mass value="10000"/>
            <inertia ixx="100"  ixy="0"  ixz="0" iyy="100" iyz="0" izz="100" />
        </inertial>
    </link>

    <joint name="base_to_obs_left" type="fixed">
        <parent link="base_link"/>
        <child link="obs_left"/>
        <origin rpy="0 0 0" xyz="-0.25 -0.1 0"/>
    </joint>

     <link name="obs_mid">
        <visual>
            <origin rpy="0.0 0.0 0.0" xyz="0.0 0.0 0.0"/>
            <geometry>
                <box size="0.05 0.8 0.05"/>
            </geometry>
            <material name="black"/>
        </visual>
        <collision>
            <origin rpy="0.0 0.0 0.0" xyz="0.0 0.0 0.0"/>
            <geometry>
                <box size="0.05 0.80 0.15"/>
            </geometry>
        </collision>
        <inertial>
            <mass value="10000"/>
            <inertia ixx="100"  ixy="0"  ixz="0" iyy="100" iyz="0" izz="100" />
        </inertial>
    </link>

    <joint name="base_to_obs_mid" type="fixed">
        <parent link="base_link"/>
        <child link="obs_mid"/>
        <origin rpy="0 0 0" xyz="0.0 0.1 0"/>
    </joint>


    <link name="obs_right">
        <visual>
            <origin rpy="0.0 0.0 0.0" xyz="0.0 0.0 0.0"/>
            <geometry>
                <box size="0.05 0.8 0.05"/>
            </geometry>
            <material name="black"/>
        </visual>
        <collision>
            <origin rpy="0.0 0.0 0.0" xyz="0.0 0.0 0.0"/>
            <geometry>
                <box size="0.05 0.80 0.15"/>
            </geometry>
        </collision>
        <inertial>
            <mass value="10000"/>
            <inertia ixx="100"  ixy="0"  ixz="0" iyy="100" iyz="0" izz="100" />
        </inertial>
    </link>

    <joint name="base_to_obs_right" type="fixed">
        <parent link="base_link"/>
        <child link="obs_right"/>
        <origin rpy="0 0 0" xyz="0.25 -0.1 0"/>
    </joint>

    <link name="bot_x">
        <origin rpy="0.0 0.0 0.0" xyz="0.0 0.0 0.0"/>
    </link>

    <link name="bot">
        <visual>
            <origin rpy="0.0 0.0 0.0" xyz="0 0 0.03"/>
            <geometry>
                <cylinder radius="0.02" length="0.05"/>
            </geometry>
            <material name="red"/>
        </visual>
        <collision>
            <origin rpy="0.0 0.0 0.0" xyz="0 0 0.03"/>
            <geometry>
                <cylinder radius="0.02" length="0.05"/>
            </geometry>
        </collision>
        <inertial>
            <origin xyz="0 0 0" rpy="0 0 0"/>
            <mass value="0.2"/>
        </inertial>
    </link>

    <joint name="base_to_bot_x" type="prismatic">
        <parent link="base_link"/>
        <child link="bot_x"/>
        <origin rpy="0 0 0" xyz="0 0 0.01"/>
        <axis xyz="1 0 0"/>
        <limit lower="-0.4" upper="3.45"/>
    </joint>

    <joint name="bot_x_to_bot" type="prismatic">
        <parent link="bot_x"/>
        <child link="bot"/>
        <origin rpy="0 0 0" xyz="0 0 0.01"/>
        <axis xyz="0 1 0"/>
        <limit lower="-0.4" upper="0.4"/>
    </joint>

    <!-- <link name="goal">
        <visual>
            <origin rpy="0.0 0.0 0.0" xyz="0 0 0.03"/>
            <geometry>
                <cylinder radius="0.05" length="0.05"/>
            </geometry>
            <material name="green"/>
        </visual>
    </link>


    <joint name="base_to_goal" type="fixed">
        <parent link="base_link"/>
        <child link="goal"/>
        <origin rpy="0 0 0" xyz="0.35 -0.4 0.01"/>
        <axis xyz="0 1 0"/>
    </joint> -->

</robot>